Workbook

Sheet 📋 Instructions
A1: PT ITSEC ASIA — COMMISSION TRACKER | HOW TO USE THIS FILE
A2: Follow these steps IN ORDER every quarter. Only one person edits at a time.
A4: STEP 1 CONFIG — SET QUARTER & RATES
B5: 👤 Owner: Finance / Sales Director | D5: 📄 Sheet: Config
B6: 1. | C6: Open the Config sheet.
B7: 2. | C7: Set the Quarter (Q1/Q2/Q3/Q4) and Year in the yellow cells.
B8: 3. | C8: Verify commission rates are correct (5% flat PIC, 3.5% Presales, etc.).
B9: 4. | C9: If the people lists have changed (new hires, role changes), update the yellow name rows at the bottom of Config.
B10: 5. | C10: Save the file.
B11: ⚠ Do this FIRST before anyone else edits. Quarter drives all date filters across the whole file.
A13: STEP 2 RAW DATA — PASTE EXPORT
B14: 👤 Owner: Finance | D14: 📄 Sheet: Raw Data
B15: 1. | C15: Open the Raw Data sheet.
B16: 2. | C16: Delete all previous quarter data (rows 4 onwards).
B17: 3. | C17: Paste the new quarterly export starting from row 3 (keep column order matching the headers).
B18: 4. | C18: Verify invoice dates are within the quarter range shown in the banner.
B19: 5. | C19: Save the file.
B20: ⚠ Do NOT change column order. Commission Data sheets auto-populate from here based on invoice dates.
A22: STEP 3 COMMISSION DATA — SALES
B23: 👤 Owner: Sales Director | D23: 📄 Sheet: Commission Data — Sales
B24: 1. | C24: Open the Commission Data — Sales sheet.
B25: 2. | C25: For each invoice row: assign Sales PIC 1 (required). Add PIC 2 / PIC 3 if the deal is shared.
B26: 3. | C26: Set Share % for each PIC — the PIC Share ⚠ column turns GREEN when shares = 100%.
B27: 4. | C27: Set Project Type: Standard (default) or Umbrella Contract. Umbrella Contract automatically applies 2.5% rate.
B28: 5. | C28: If Umbrella Contract: assign PM Name.
B29: 6. | C29: Assign Sales Manager and Sales Director names per row.
B30: 7. | C30: Add Referral person(s) and share % if applicable.
B31: 8. | C31: Save and pass file to Presales Manager.
B32: ⚠ PIC shares must sum to 100% per row. Check the ⚠ column — red = over 100%, amber = under 100%.
A34: STEP 4 COMMISSION DATA — PRESALES
B35: 👤 Owner: Presales Manager | D35: 📄 Sheet: Commission Data — Presales
B36: 1. | C36: Open the Commission Data — Presales sheet.
B37: 2. | C37: Invoice rows are already populated from Raw Data.
B38: 3. | C38: For each relevant invoice: assign Presales 1 (and Presales 2/3 if shared).
B39: 4. | C39: Set Share % for each presales person — PS Share ⚠ turns GREEN at 100%.
B40: 5. | C40: Leave rows blank where no presales involvement.
B41: 6. | C41: Save and return file to Sales Director.
B42: ⚠ Presales shares must sum to 100% per row when presales is involved. Not all deals need presales.
A43: STEP 5 INDIVIDUAL SLIPS — SHARE WITH TEAM
B44: 👤 Owner: Sales Director | D44: 📄 Sheet: Individual name tabs
...

Sheet Config
A1: PT ITSEC ASIA — COMMISSION TRACKER CONFIGURATION
A2: Change YELLOW cells only. All sheets update automatically.
B4: Setting | C4: Value | D4: Result / Notes
B5: Quarter | C5: Q1 | D5: Q1 / Q2 / Q3 / Q4
B6: Year | C6: 2026 | D6: 4-digit year
B7: Quarter Label | C7: =C5&" "&C6 -> Q1 2026 | D7: Auto: "Q1 2026"
B8: Quarter Start | C8: =DATE(C6,IF(C5="Q1",1,IF(C5="Q2",4,IF(C5="Q3",7,10))),1) -> 46023 | D8: First day of selected quarter
B9: Quarter End | C9: =DATE(C6,IF(C5="Q1",3,IF(C5="Q2",6,IF(C5="Q3",9,12))),31) -> 46112 | D9: Last day of selected quarter
B10: Payout Deadline | C10: =DATE(C6+IF(C5="Q4",1,0),IF(C5="Q1",4,IF(C5="Q2",7,IF(C5="Q3",10,1))),30) -> 46142 | D10: 30 days after quarter end
B11: Report Title | C11: ="PT ITSEC ASIA — SALES COMMISSION TRACKER "&C7 -> PT ITSEC ASIA — SALES COMMISSION TRACKER Q1 2026 | D11: Used in all banners
B13: MARGIN CALCULATION RULES
B14: Status = "Closed" exactly | C14: MIN(Est. Margin, Final Margin) | D14: Uses most conservative figure. Final margin confirmed in PSOhub.
B15: All other statuses (Active, Partially Closed, Closed - Missing Orange…) | C15: Estimated Margin only | D15: Actual margin not yet confirmed. Adjusted at project close.
B16: Est. Margin source: PSOHUB col filled | C16: PSO Hub Est. Margin (col P) | D16: Project in PSOhub → use PSOhub estimated margin
B17: Est. Margin source: PSOHUB col blank | C17: Deal Sheet Margin (col R) | D17: Pre-PSOhub project → use Deal Sheet margin as estimated
B19: Rate Setting | C19: Rate | D19: Notes
B20: Sales PIC – Quarterly Rate (Standard) | C20: 0.05 | D20: ← C20 Flat 5% paid every quarter. Tier uplift reconciled at year-end.
B21: Sales PIC – Umbrella Contract rate (total pool) | C21: 0.025 | D21: ← C21 Umbrella Contract: PIC pool 2.5%×share%. PM gets 2.5% separately.
B22: PM – Umbrella Contract rate | C22: 0.025 | D22: ← C22 PM always earns 2.5% of applied comm base on Umbrella Contract.
B23: Sales Manager commission | C23: 0.007 | D23: ← C23
B24: Sales Director commission | C24: 0.003 | D24: ← C24
B25: Presales commission | C25: 0.035 | D25: ← C25
B26: Employee Referral pool (% of margin) | C26: 0.01 | D26: ← C26 1% deducted from PIC net.
B29: 👥 DROPDOWN PEOPLE LISTS (edit here to update all dropdowns)
B30: Role
B31: Sales Director | C31: Eko P W | D31: Add names in yellow rows ↓ — dropdowns update automatically
B37: Sales Manager | C37: Esther Maggie | D37: Add names in yellow rows ↓ — dropdowns update automatically
C38: Eka Yulianti
B44: Sales PIC | C44: Rafi Zafran | D44: Add names in yellow rows ↓ — dropdowns update automatically
C45: Krestianto Aditya
C46: Fakhri Ahmad
C47: Arditha Anggun
C48: Meirika Tambunan
C49: Rivanya Marsha
C50: Rizki Arisanti
C51: Esther Maggie
C52: Eka Yulianti
B56: Presales | C56: Andy Wijaya | D56: Add names in yellow rows ↓ — dropdowns update automatically
C57: Atik Pilihanto
C58: Arief Muttaqien
...

Sheet Raw Data
A1: =Config!C11&" — RAW DATA (PSOhub Export)" -> PT ITSEC ASIA — SALES COMMISSION TRACKER Q1 2026 — RAW DATA (PSOhub Export)
A2: 📥 Paste raw data here from row 3. Keep column order matching the headers below.
A3: Service Type | B3: Client Name | C3: Invoice No. | D3: PSOHUB | E3: Project Status | F3: Start Date | G3: Reference | H3: Description | I3: Invoice Date | J3: Due Date | K3: Amount (Gross) | L3: Tax | M3: WHT & Penalty | N3: Cash In | O3: Revenue (Net) | P3: PSO Hub Est. Margin | Q3: PSO Hub Final Margin | R3: Deal Sheet Margin | S3: Commission Base (Source)
A4: Pentest | B4: PT Dummy Bank Tbk | C4: INV-990001 | D4: PRO-2026-901 | E4: Closed | F4: 46032 | G4: PO 001/DUMMY/2026 | H4: Web Application Penetration Test - Phase 1 | I4: 46037 | J4: 46068 | K4: 200000000 | L4: 22000000 | M4: 4000000 | N4: 218000000 | O4: 196000000 | Q4: 0.45 | S4: 88200000
A5: Governance | B5: PT Dummy Insurance | C5: INV-990002 | D5: PRO-2026-902 | E5: Active | F5: 46054 | G5: PO 002/DUMMY/2026 | H5: GRC Framework Assessment & Remediation Term 1 - 50% | I5: 46063 | J5: 46096 | K5: 150000000 | L5: 16500000 | M5: 3000000 | N5: 163500000 | O5: 147000000 | P5: 0.35 | S5: 51450000
A6: Solution | B6: PT Dummy Telco | C6: INV-990003 | D6: PRO-2026-903 | E6: Closed | F6: 46027 | G6: PO 003/DUMMY/2026 | H6: Managed SOC Services - Month 3 | I6: 46082 | J6: 46113 | K6: 350000000 | L6: 38500000 | M6: 7000000 | N6: 381500000 | O6: 343000000 | Q6: 0.3 | S6: 102900000
A7: MSS | B7: PT Dummy Energy | C7: INV-990004 | D7: PRO-2026-904 | E7: Closed - Missing Orange | F7: 45981 | G7: PO 004/DUMMY/2026 | H7: Vulnerability Assessment & License Renewal | I7: 46042 | J7: 46073 | K7: 500000000 | L7: 55000000 | M7: 10000000 | N7: 545000000 | O7: 490000000 | P7: 0.25 | S7: 122500000
A8: Forensic | B8: PT Dummy Retail | C8: INV-990005 | E8: Active | G8: PKS 005/DUMMY/2026 | H8: Digital Forensic Investigation - Term 1 - 40% | I8: 46101 | J8: 46132 | K8: 180000000 | L8: 19800000 | M8: 3600000 | N8: 196200000 | O8: 176400000 | P8: 0.4 | S8: 70560000

Sheet Commission Data — Sales
A1: =Config!C11&" — COMMISSION DATA | SALES" -> PT ITSEC ASIA — SALES COMMISSION TRACKER Q1 2026 — COMMISSION DATA | SALES
A2: =Config!C7&" | Payout: "&TEXT(Config!C10,"DD-MMM-YYYY")&" | PIC: 5% flat (year-end tier recon) | Umbrella Contract: 2.5%×share | PM 2.5% | Mgr 0.7% | Dir 0.3% | Ref 1%" -> Q1 2026 | Payout: 30-Apr-2026 | PIC: 5% flat (year-end tier recon) | Umbrella Contract: 2.5%×share | PM 2.5% | Mgr 0.7% | Dir 0.3% | Ref 1%
A3: ="Quarter: "&Config!C7&" | "&TEXT(Config!C8,"DD-MMM-YYYY")&" → "&TEXT(Config!C9,"DD-MMM-YYYY") -> Quarter: Q1 2026 | 01-Jan-2026 → 31-Mar-2026
A5: DEAL INFO | E5: FINANCIALS & MARGIN | N5: PROJECT TYPE | O5: SALES PIC (up to 3) — share-based | AA5: PM — Umbrella Contract only | AC5: SALES MANAGER | AE5: SALES DIRECTOR | AG5: REFERRAL (free text) | AP5: PIC Share ⚠ | AQ5: PIC NET COMM | AT5: PIC NET COMM
A6: # | B6: Service Type | C6: Client | D6: Invoice | E6: PSOHUB | F6: Status | G6: Description | H6: Date | I6: Rev Net | J6: Est. Margin | K6: Final Margin | L6: APPLIED MARGIN | M6: Comm Base | N6: Project Type | O6: PIC 1 Name | P6: PIC 1 Share% | Q6: PIC 1 Rate | R6: PIC 1 Comm | S6: PIC 2 Name | T6: PIC 2 Share% | U6: PIC 2 Rate | V6: PIC 2 Comm | W6: PIC 3 Name | X6: PIC 3 Share% | Y6: PIC 3 Rate | Z6: PIC 3 Comm | AA6: PM Name | AB6: PM Comm | AC6: Mgr Name | AD6: Mgr Comm | AE6: Dir Name | AF6: Dir Comm | AG6: Ref 1 Name | AH6: Ref 1 % | AI6: Ref 1 Comm | AJ6: Ref 2 Name | AK6: Ref 2 % | AL6: Ref 2 Comm | AM6: Ref 3 Name | AN6: Ref 3 % | AO6: Ref 3 Comm | AP6: PIC Share ⚠ | AQ6: PIC 1 NET | AR6: PIC 2 NET | AS6: PIC 3 NET
A7: 4 | B7: =IF(A7<>"",INDEX('Raw Data'!$A$4:$A$203,A7-4+1),"") -> Pentest | C7: =IF(A7<>"",INDEX('Raw Data'!$B$4:$B$203,A7-4+1),"") -> PT Dummy Bank Tbk | D7: =IF(A7<>"",INDEX('Raw Data'!$C$4:$C$203,A7-4+1),"") -> INV-990001 | E7: =IF(A7<>"",INDEX('Raw Data'!$D$4:$D$203,A7-4+1),"") -> PRO-2026-901 | F7: =IF(A7<>"",INDEX('Raw Data'!$E$4:$E$203,A7-4+1),"") -> Closed | G7: =IF(A7<>"",INDEX('Raw Data'!$H$4:$H$203,A7-4+1),"") -> Web Application Penetration Test - Phase 1 | H7: =IF(A7<>"",INDEX('Raw Data'!$I$4:$I$203,A7-4+1),"") -> 46037 | I7: =IF(A7<>"",INDEX('Raw Data'!$O$4:$O$203,A7-4+1),"") -> 196000000 | J7: =IF(A7<>"",IF(INDEX('Raw Data'!$D$4:$D$203,A7-4+1)<>"",INDEX('Raw Data'!$P$4:$P$203,A7-4+1),INDEX('Raw Data'!$R$4:$R$203,A7-4+1)),"") -> 0 | K7: =IF(A7<>"",IF(INDEX('Raw Data'!$Q$4:$Q$203,A7-4+1)<>"",INDEX('Raw Data'!$Q$4:$Q$203,A7-4+1),""),"") -> 0.45 | L7: =IF(NOT(A7<>""),"",IF(EXACT(TRIM(F7),"Closed"),IF(K7="",J7,MIN(J7,K7)),J7)) -> 0 | M7: =IF(A7<>"",INDEX('Raw Data'!$S$4:$S$203,A7-4+1),0) -> 88200000 | N7: Standard | O7: Arditha Anggun | P7: 1 | Q7: =IF(O7="",0,IF(N7="Umbrella Contract",Config!$C$21,Config!$C$20)) -> 0.05 | R7: =IF(O7="",0,M7*Q7*P7) -> 4410000 | T7: 0 | U7: =IF(S7="",0,IF(N7="Umbrella Contract",Config!$C$21,Config!$C$20)) -> 0 | V7: =IF(S7="",0,M7*U7*T7) -> 0 | X7: 0 | Y7: =IF(W7="",0,IF(N7="Umbrella Contract",Config!$C$21,Config!$C$20)) -> 0 | Z7: =IF(W7="",0,M7*Y7*X7) -> 0 | AB7: =IF(OR(N7<>"Umbrella Contract",AA7=""),0,M7*Config!$C$22) -> 0 | AC7: Esther Maggie | AD7: =IF(OR(AC7="",AC7=O7,AC7=S7,AC7=W7),0,M7*Config!$C$23) -> 617400 | AE7: Eko P W | AF7: =IF(OR(AE7="",AE7=O7,AE7=S7,AE7=W7),0,M7*Config!$C$24) -> 264600 | AH7: 0 | AI7: =IF(AG7="",0,M7*Config!$C$26*AH7) -> 0 | AK7: 0 | AL7: =IF(AJ7="",0,M7*Config!$C$26*AK7) -> 0 | AN7: 0 | AO7: =IF(AM7="",0,M7*Config!$C$26*AN7) -> 0 | AP7: =IF(AND(O7="",S7="",W7=""),"",P7+T7+X7) -> 1 | AQ7: =IF(R7=0,0,R7-IF((R7+V7+Z7)=0,0,(AI7+AL7+AO7)*(R7/(R7+V7+Z7)))) -> 4410000 | AR7: =IF(V7=0,0,V7-IF((R7+V7+Z7)=0,0,(AI7+AL7+AO7)*(V7/(R7+V7+Z7)))) -> 0 | AS7: =IF(Z7=0,0,Z7-IF((R7+V7+Z7)=0,0,(AI7+AL7+AO7)*(Z7/(R7+V7+Z7)))) -> 0
A8: 5 | B8: =IF(A8<>"",INDEX('Raw Data'!$A$4:$A$203,A8-4+1),"") -> Governance | C8: =IF(A8<>"",INDEX('Raw Data'!$B$4:$B$203,A8-4+1),"") -> PT Dummy Insurance | D8: =IF(A8<>"",INDEX('Raw Data'!$C$4:$C$203,A8-4+1),"") -> INV-990002 | E8: =IF(A8<>"",INDEX('Raw Data'!$D$4:$D$203,A8-4+1),"") -> PRO-2026-902 | F8: =IF(A8<>"",INDEX('Raw Data'!$E$4:$E$203,A8-4+1),"") -> Active | G8: =IF(A8<>"",INDEX('Raw Data'!$H$4:$H$203,A8-4+1),"") -> GRC Framework Assessment & Remediation Term 1 - 50% | H8: =IF(A8<>"",INDEX('Raw Data'!$I$4:$I$203,A8-4+1),"") -> 46063 | I8: =IF(A8<>"",INDEX('Raw Data'!$O$4:$O$203,A8-4+1),"") -> 147000000 | J8: =IF(A8<>"",IF(INDEX('Raw Data'!$D$4:$D$203,A8-4+1)<>"",INDEX('Raw Data'!$P$4:$P$203,A8-4+1),INDEX('Raw Data'!$R$4:$R$203,A8-4+1)),"") -> 0.35 | K8: =IF(A8<>"",IF(INDEX('Raw Data'!$Q$4:$Q$203,A8-4+1)<>"",INDEX('Raw Data'!$Q$4:$Q$203,A8-4+1),""),"") | L8: =IF(NOT(A8<>""),"",IF(EXACT(TRIM(F8),"Closed"),IF(K8="",J8,MIN(J8,K8)),J8)) -> 0.35 | M8: =IF(A8<>"",INDEX('Raw Data'!$S$4:$S$203,A8-4+1),0) -> 51450000 | N8: Standard | O8: Rivanya Marsha | P8: 1 | Q8: =IF(O8="",0,IF(N8="Umbrella Contract",Config!$C$21,Config!$C$20)) -> 0.05 | R8: =IF(O8="",0,M8*Q8*P8) -> 2572500 | T8: 0 | U8: =IF(S8="",0,IF(N8="Umbrella Contract",Config!$C$21,Config!$C$20)) -> 0 | V8: =IF(S8="",0,M8*U8*T8) -> 0 | X8: 0 | Y8: =IF(W8="",0,IF(N8="Umbrella Contract",Config!$C$21,Config!$C$20)) -> 0 | Z8: =IF(W8="",0,M8*Y8*X8) -> 0 | AB8: =IF(OR(N8<>"Umbrella Contract",AA8=""),0,M8*Config!$C$22) -> 0 | AC8: Esther Maggie | AD8: =IF(OR(AC8="",AC8=O8,AC8=S8,AC8=W8),0,M8*Config!$C$23) -> 360150 | AE8: Eko P W | AF8: =IF(OR(AE8="",AE8=O8,AE8=S8,AE8=W8),0,M8*Config!$C$24) -> 154350 | AH8: 0 | AI8: =IF(AG8="",0,M8*Config!$C$26*AH8) -> 0 | AK8: 0 | AL8: =IF(AJ8="",0,M8*Config!$C$26*AK8) -> 0 | AN8: 0 | AO8: =IF(AM8="",0,M8*Config!$C$26*AN8) -> 0 | AP8: =IF(AND(O8="",S8="",W8=""),"",P8+T8+X8) -> 1 | AQ8: =IF(R8=0,0,R8-IF((R8+V8+Z8)=0,0,(AI8+AL8+AO8)*(R8/(R8+V8+Z8)))) -> 2572500 | AR8: =IF(V8=0,0,V8-IF((R8+V8+Z8)=0,0,(AI8+AL8+AO8)*(V8/(R8+V8+Z8)))) -> 0 | AS8: =IF(Z8=0,0,Z8-IF((R8+V8+Z8)=0,0,(AI8+AL8+AO8)*(Z8/(R8+V8+Z8)))) -> 0
A9: 6 | B9: =IF(A9<>"",INDEX('Raw Data'!$A$4:$A$203,A9-4+1),"") -> Solution | C9: =IF(A9<>"",INDEX('Raw Data'!$B$4:$B$203,A9-4+1),"") -> PT Dummy Telco | D9: =IF(A9<>"",INDEX('Raw Data'!$C$4:$C$203,A9-4+1),"") -> INV-990003 | E9: =IF(A9<>"",INDEX('Raw Data'!$D$4:$D$203,A9-4+1),"") -> PRO-2026-903 | F9: =IF(A9<>"",INDEX('Raw Data'!$E$4:$E$203,A9-4+1),"") -> Closed | G9: =IF(A9<>"",INDEX('Raw Data'!$H$4:$H$203,A9-4+1),"") -> Managed SOC Services - Month 3 | H9: =IF(A9<>"",INDEX('Raw Data'!$I$4:$I$203,A9-4+1),"") -> 46082 | I9: =IF(A9<>"",INDEX('Raw Data'!$O$4:$O$203,A9-4+1),"") -> 343000000 | J9: =IF(A9<>"",IF(INDEX('Raw Data'!$D$4:$D$203,A9-4+1)<>"",INDEX('Raw Data'!$P$4:$P$203,A9-4+1),INDEX('Raw Data'!$R$4:$R$203,A9-4+1)),"") -> 0 | K9: =IF(A9<>"",IF(INDEX('Raw Data'!$Q$4:$Q$203,A9-4+1)<>"",INDEX('Raw Data'!$Q$4:$Q$203,A9-4+1),""),"") -> 0.3 | L9: =IF(NOT(A9<>""),"",IF(EXACT(TRIM(F9),"Closed"),IF(K9="",J9,MIN(J9,K9)),J9)) -> 0 | M9: =IF(A9<>"",INDEX('Raw Data'!$S$4:$S$203,A9-4+1),0) -> 102900000 | N9: Umbrella Contract | O9: Krestianto Aditya | P9: 1 | Q9: =IF(O9="",0,IF(N9="Umbrella Contract",Config!$C$21,Config!$C$20)) -> 0.025 | R9: =IF(O9="",0,M9*Q9*P9) -> 2572500 | T9: 0 | U9: =IF(S9="",0,IF(N9="Umbrella Contract",Config!$C$21,Config!$C$20)) -> 0 | V9: =IF(S9="",0,M9*U9*T9) -> 0 | X9: 0 | Y9: =IF(W9="",0,IF(N9="Umbrella Contract",Config!$C$21,Config!$C$20)) -> 0 | Z9: =IF(W9="",0,M9*Y9*X9) -> 0 | AA9: Andi Sunandi | AB9: =IF(OR(N9<>"Umbrella Contract",AA9=""),0,M9*Config!$C$22) -> 2572500 | AC9: Esther Maggie | AD9: =IF(OR(AC9="",AC9=O9,AC9=S9,AC9=W9),0,M9*Config!$C$23) -> 720300 | AE9: Eko P W | AF9: =IF(OR(AE9="",AE9=O9,AE9=S9,AE9=W9),0,M9*Config!$C$24) -> 308700 | AH9: 0 | AI9: =IF(AG9="",0,M9*Config!$C$26*AH9) -> 0 | AK9: 0 | AL9: =IF(AJ9="",0,M9*Config!$C$26*AK9) -> 0 | AN9: 0 | AO9: =IF(AM9="",0,M9*Config!$C$26*AN9) -> 0 | AP9: =IF(AND(O9="",S9="",W9=""),"",P9+T9+X9) -> 1 | AQ9: =IF(R9=0,0,R9-IF((R9+V9+Z9)=0,0,(AI9+AL9+AO9)*(R9/(R9+V9+Z9)))) -> 2572500 | AR9: =IF(V9=0,0,V9-IF((R9+V9+Z9)=0,0,(AI9+AL9+AO9)*(V9/(R9+V9+Z9)))) -> 0 | AS9: =IF(Z9=0,0,Z9-IF((R9+V9+Z9)=0,0,(AI9+AL9+AO9)*(Z9/(R9+V9+Z9)))) -> 0
A10: 7 | B10: =IF(A10<>"",INDEX('Raw Data'!$A$4:$A$203,A10-4+1),"") -> MSS | C10: =IF(A10<>"",INDEX('Raw Data'!$B$4:$B$203,A10-4+1),"") -> PT Dummy Energy | D10: =IF(A10<>"",INDEX('Raw Data'!$C$4:$C$203,A10-4+1),"") -> INV-990004 | E10: =IF(A10<>"",INDEX('Raw Data'!$D$4:$D$203,A10-4+1),"") -> PRO-2026-904 | F10: =IF(A10<>"",INDEX('Raw Data'!$E$4:$E$203,A10-4+1),"") -> Closed - Missing Orange | G10: =IF(A10<>"",INDEX('Raw Data'!$H$4:$H$203,A10-4+1),"") -> Vulnerability Assessment & License Renewal | H10: =IF(A10<>"",INDEX('Raw Data'!$I$4:$I$203,A10-4+1),"") -> 46042 | I10: =IF(A10<>"",INDEX('Raw Data'!$O$4:$O$203,A10-4+1),"") -> 490000000 | J10: =IF(A10<>"",IF(INDEX('Raw Data'!$D$4:$D$203,A10-4+1)<>"",INDEX('Raw Data'!$P$4:$P$203,A10-4+1),INDEX('Raw Data'!$R$4:$R$203,A10-4+1)),"") -> 0.25 | K10: =IF(A10<>"",IF(INDEX('Raw Data'!$Q$4:$Q$203,A10-4+1)<>"",INDEX('Raw Data'!$Q$4:$Q$203,A10-4+1),""),"") | L10: =IF(NOT(A10<>""),"",IF(EXACT(TRIM(F10),"Closed"),IF(K10="",J10,MIN(J10,K10)),J10)) -> 0.25 | M10: =IF(A10<>"",INDEX('Raw Data'!$S$4:$S$203,A10-4+1),0) -> 122500000 | N10: Standard | O10: Meirika Tambunan | P10: 0.6 | Q10: =IF(O10="",0,IF(N10="Umbrella Contract",Config!$C$21,Config!$C$20)) -> 0.05 | R10: =IF(O10="",0,M10*Q10*P10) -> 3675000 | S10: Fakhri Ahmad | T10: 0.4 | U10: =IF(S10="",0,IF(N10="Umbrella Contract",Config!$C$21,Config!$C$20)) -> 0.05 | V10: =IF(S10="",0,M10*U10*T10) -> 2450000 | X10: 0 | Y10: =IF(W10="",0,IF(N10="Umbrella Contract",Config!$C$21,Config!$C$20)) -> 0 | Z10: =IF(W10="",0,M10*Y10*X10) -> 0 | AB10: =IF(OR(N10<>"Umbrella Contract",AA10=""),0,M10*Config!$C$22) -> 0 | AC10: Esther Maggie | AD10: =IF(OR(AC10="",AC10=O10,AC10=S10,AC10=W10),0,M10*Config!$C$23) -> 857500 | AE10: Eko P W | AF10: =IF(OR(AE10="",AE10=O10,AE10=S10,AE10=W10),0,M10*Config!$C$24) -> 367500 | AH10: 0 | AI10: =IF(AG10="",0,M10*Config!$C$26*AH10) -> 0 | AK10: 0 | AL10: =IF(AJ10="",0,M10*Config!$C$26*AK10) -> 0 | AN10: 0 | AO10: =IF(AM10="",0,M10*Config!$C$26*AN10) -> 0 | AP10: =IF(AND(O10="",S10="",W10=""),"",P10+T10+X10) -> 1 | AQ10: =IF(R10=0,0,R10-IF((R10+V10+Z10)=0,0,(AI10+AL10+AO10)*(R10/(R10+V10+Z10)))) -> 3675000 | AR10: =IF(V10=0,0,V10-IF((R10+V10+Z10)=0,0,(AI10+AL10+AO10)*(V10/(R10+V10+Z10)))) -> 2450000 | AS10: =IF(Z10=0,0,Z10-IF((R10+V10+Z10)=0,0,(AI10+AL10+AO10)*(Z10/(R10+V10+Z10)))) -> 0
A11: 8 | B11: =IF(A11<>"",INDEX('Raw Data'!$A$4:$A$203,A11-4+1),"") -> Forensic | C11: =IF(A11<>"",INDEX('Raw Data'!$B$4:$B$203,A11-4+1),"") -> PT Dummy Retail | D11: =IF(A11<>"",INDEX('Raw Data'!$C$4:$C$203,A11-4+1),"") -> INV-990005 | E11: =IF(A11<>"",INDEX('Raw Data'!$D$4:$D$203,A11-4+1),"") -> 0 | F11: =IF(A11<>"",INDEX('Raw Data'!$E$4:$E$203,A11-4+1),"") -> Active | G11: =IF(A11<>"",INDEX('Raw Data'!$H$4:$H$203,A11-4+1),"") -> Digital Forensic Investigation - Term 1 - 40% | H11: =IF(A11<>"",INDEX('Raw Data'!$I$4:$I$203,A11-4+1),"") -> 46101 | I11: =IF(A11<>"",INDEX('Raw Data'!$O$4:$O$203,A11-4+1),"") -> 176400000 | J11: =IF(A11<>"",IF(INDEX('Raw Data'!$D$4:$D$203,A11-4+1)<>"",INDEX('Raw Data'!$P$4:$P$203,A11-4+1),INDEX('Raw Data'!$R$4:$R$203,A11-4+1)),"") -> 0 | K11: =IF(A11<>"",IF(INDEX('Raw Data'!$Q$4:$Q$203,A11-4+1)<>"",INDEX('Raw Data'!$Q$4:$Q$203,A11-4+1),""),"") | L11: =IF(NOT(A11<>""),"",IF(EXACT(TRIM(F11),"Closed"),IF(K11="",J11,MIN(J11,K11)),J11)) -> 0 | M11: =IF(A11<>"",INDEX('Raw Data'!$S$4:$S$203,A11-4+1),0) -> 70560000 | N11: Standard | O11: Rafi Zafran | P11: 1 | Q11: =IF(O11="",0,IF(N11="Umbrella Contract",Config!$C$21,Config!$C$20)) -> 0.05 | R11: =IF(O11="",0,M11*Q11*P11) -> 3528000 | T11: 0 | U11: =IF(S11="",0,IF(N11="Umbrella Contract",Config!$C$21,Config!$C$20)) -> 0 | V11: =IF(S11="",0,M11*U11*T11) -> 0 | X11: 0 | Y11: =IF(W11="",0,IF(N11="Umbrella Contract",Config!$C$21,Config!$C$20)) -> 0 | Z11: =IF(W11="",0,M11*Y11*X11) -> 0 | AB11: =IF(OR(N11<>"Umbrella Contract",AA11=""),0,M11*Config!$C$22) -> 0 | AC11: Esther Maggie | AD11: =IF(OR(AC11="",AC11=O11,AC11=S11,AC11=W11),0,M11*Config!$C$23) -> 493920 | AE11: Eko P W | AF11: =IF(OR(AE11="",AE11=O11,AE11=S11,AE11=W11),0,M11*Config!$C$24) -> 211680 | AG11: Rizki Arisanti | AH11: 1 | AI11: =IF(AG11="",0,M11*Config!$C$26*AH11) -> 705600 | AK11: 0 | AL11: =IF(AJ11="",0,M11*Config!$C$26*AK11) -> 0 | AN11: 0 | AO11: =IF(AM11="",0,M11*Config!$C$26*AN11) -> 0 | AP11: =IF(AND(O11="",S11="",W11=""),"",P11+T11+X11) -> 1 | AQ11: =IF(R11=0,0,R11-IF((R11+V11+Z11)=0,0,(AI11+AL11+AO11)*(R11/(R11+V11+Z11)))) -> 2822400 | AR11: =IF(V11=0,0,V11-IF((R11+V11+Z11)=0,0,(AI11+AL11+AO11)*(V11/(R11+V11+Z11)))) -> 0 | AS11: =IF(Z11=0,0,Z11-IF((R11+V11+Z11)=0,0,(AI11+AL11+AO11)*(Z11/(R11+V11+Z11)))) -> 0
B154: =IF(A154<>"",INDEX('Raw Data'!$A$4:$A$203,A154-4+1),"") | C154: =IF(A154<>"",INDEX('Raw Data'!$B$4:$B$203,A154-4+1),"") | D154: =IF(A154<>"",INDEX('Raw Data'!$C$4:$C$203,A154-4+1),"") | E154: =IF(A154<>"",INDEX('Raw Data'!$D$4:$D$203,A154-4+1),"") | F154: =IF(A154<>"",INDEX('Raw Data'!$E$4:$E$203,A154-4+1),"") | G154: =IF(A154<>"",INDEX('Raw Data'!$H$4:$H$203,A154-4+1),"") | H154: =IF(A154<>"",INDEX('Raw Data'!$I$4:$I$203,A154-4+1),"") | I154: =IF(A154<>"",INDEX('Raw Data'!$O$4:$O$203,A154-4+1),"") | J154: =IF(A154<>"",IF(INDEX('Raw Data'!$D$4:$D$203,A154-4+1)<>"",INDEX('Raw Data'!$P$4:$P$203,A154-4+1),INDEX('Raw Data'!$R$4:$R$203,A154-4+1)),"") | K154: =IF(A154<>"",IF(INDEX('Raw Data'!$Q$4:$Q$203,A154-4+1)<>"",INDEX('Raw Data'!$Q$4:$Q$203,A154-4+1),""),"") | L154: =IF(NOT(A154<>""),"",IF(EXACT(TRIM(F154),"Closed"),IF(K154="",J154,MIN(J154,K154)),J154)) | M154: =IF(A154<>"",INDEX('Raw Data'!$S$4:$S$203,A154-4+1),0) -> 0 | N154: Standard | P154: 1 | Q154: =IF(O154="",0,IF(N154="Umbrella Contract",Config!$C$21,Config!$C$20)) -> 0 | R154: =IF(O154="",0,M154*Q154*P154) -> 0 | T154: 0 | U154: =IF(S154="",0,IF(N154="Umbrella Contract",Config!$C$21,Config!$C$20)) -> 0 | V154: =IF(S154="",0,M154*U154*T154) -> 0 | X154: 0 | Y154: =IF(W154="",0,IF(N154="Umbrella Contract",Config!$C$21,Config!$C$20)) -> 0 | Z154: =IF(W154="",0,M154*Y154*X154) -> 0 | AB154: =IF(OR(N154<>"Umbrella Contract",AA154=""),0,M154*Config!$C$22) -> 0 | AD154: =IF(OR(AC154="",AC154=O154,AC154=S154,AC154=W154),0,M154*Config!$C$23) -> 0 | AF154: =IF(OR(AE154="",AE154=O154,AE154=S154,AE154=W154),0,M154*Config!$C$24) -> 0 | AH154: 1 | AI154: =IF(AG154="",0,M154*Config!$C$26*AH154) -> 0 | AK154: 0 | AL154: =IF(AJ154="",0,M154*Config!$C$26*AK154) -> 0 | AN154: 0 | AO154: =IF(AM154="",0,M154*Config!$C$26*AN154) -> 0 | AP154: =IF(AND(O154="",S154="",W154=""),"",P154+T154+X154) | AQ154: =IF(R154=0,0,R154-IF((R154+V154+Z154)=0,0,(AI154+AL154+AO154)*(R154/(R154+V154+Z154)))) -> 0 | AR154: =IF(V154=0,0,V154-IF((R154+V154+Z154)=0,0,(AI154+AL154+AO154)*(V154/(R154+V154+Z154)))) -> 0 | AS154: =IF(Z154=0,0,Z154-IF((R154+V154+Z154)=0,0,(AI154+AL154+AO154)*(Z154/(R154+V154+Z154)))) -> 0
B155: =IF(A155<>"",INDEX('Raw Data'!$A$4:$A$203,A155-4+1),"") | C155: =IF(A155<>"",INDEX('Raw Data'!$B$4:$B$203,A155-4+1),"") | D155: =IF(A155<>"",INDEX('Raw Data'!$C$4:$C$203,A155-4+1),"") | E155: =IF(A155<>"",INDEX('Raw Data'!$D$4:$D$203,A155-4+1),"") | F155: =IF(A155<>"",INDEX('Raw Data'!$E$4:$E$203,A155-4+1),"") | G155: =IF(A155<>"",INDEX('Raw Data'!$H$4:$H$203,A155-4+1),"") | H155: =IF(A155<>"",INDEX('Raw Data'!$I$4:$I$203,A155-4+1),"") | I155: =IF(A155<>"",INDEX('Raw Data'!$O$4:$O$203,A155-4+1),"") | J155: =IF(A155<>"",IF(INDEX('Raw Data'!$D$4:$D$203,A155-4+1)<>"",INDEX('Raw Data'!$P$4:$P$203,A155-4+1),INDEX('Raw Data'!$R$4:$R$203,A155-4+1)),"") | K155: =IF(A155<>"",IF(INDEX('Raw Data'!$Q$4:$Q$203,A155-4+1)<>"",INDEX('Raw Data'!$Q$4:$Q$203,A155-4+1),""),"") | L155: =IF(NOT(A155<>""),"",IF(EXACT(TRIM(F155),"Closed"),IF(K155="",J155,MIN(J155,K155)),J155)) | M155: =IF(A155<>"",INDEX('Raw Data'!$S$4:$S$203,A155-4+1),0) -> 0 | N155: Standard | P155: 1 | Q155: =IF(O155="",0,IF(N155="Umbrella Contract",Config!$C$21,Config!$C$20)) -> 0 | R155: =IF(O155="",0,M155*Q155*P155) -> 0 | T155: 0 | U155: =IF(S155="",0,IF(N155="Umbrella Contract",Config!$C$21,Config!$C$20)) -> 0 | V155: =IF(S155="",0,M155*U155*T155) -> 0 | X155: 0 | Y155: =IF(W155="",0,IF(N155="Umbrella Contract",Config!$C$21,Config!$C$20)) -> 0 | Z155: =IF(W155="",0,M155*Y155*X155) -> 0 | AB155: =IF(OR(N155<>"Umbrella Contract",AA155=""),0,M155*Config!$C$22) -> 0 | AD155: =IF(OR(AC155="",AC155=O155,AC155=S155,AC155=W155),0,M155*Config!$C$23) -> 0 | AF155: =IF(OR(AE155="",AE155=O155,AE155=S155,AE155=W155),0,M155*Config!$C$24) -> 0 | AH155: 1 | AI155: =IF(AG155="",0,M155*Config!$C$26*AH155) -> 0 | AK155: 0 | AL155: =IF(AJ155="",0,M155*Config!$C$26*AK155) -> 0 | AN155: 0 | AO155: =IF(AM155="",0,M155*Config!$C$26*AN155) -> 0 | AP155: =IF(AND(O155="",S155="",W155=""),"",P155+T155+X155) | AQ155: =IF(R155=0,0,R155-IF((R155+V155+Z155)=0,0,(AI155+AL155+AO155)*(R155/(R155+V155+Z155)))) -> 0 | AR155: =IF(V155=0,0,V155-IF((R155+V155+Z155)=0,0,(AI155+AL155+AO155)*(V155/(R155+V155+Z155)))) -> 0 | AS155: =IF(Z155=0,0,Z155-IF((R155+V155+Z155)=0,0,(AI155+AL155+AO155)*(Z155/(R155+V155+Z155)))) -> 0
B156: =IF(A156<>"",INDEX('Raw Data'!$A$4:$A$203,A156-4+1),"") | C156: =IF(A156<>"",INDEX('Raw Data'!$B$4:$B$203,A156-4+1),"") | D156: =IF(A156<>"",INDEX('Raw Data'!$C$4:$C$203,A156-4+1),"") | E156: =IF(A156<>"",INDEX('Raw Data'!$D$4:$D$203,A156-4+1),"") | F156: =IF(A156<>"",INDEX('Raw Data'!$E$4:$E$203,A156-4+1),"") | G156: =IF(A156<>"",INDEX('Raw Data'!$H$4:$H$203,A156-4+1),"") | H156: =IF(A156<>"",INDEX('Raw Data'!$I$4:$I$203,A156-4+1),"") | I156: =IF(A156<>"",INDEX('Raw Data'!$O$4:$O$203,A156-4+1),"") | J156: =IF(A156<>"",IF(INDEX('Raw Data'!$D$4:$D$203,A156-4+1)<>"",INDEX('Raw Data'!$P$4:$P$203,A156-4+1),INDEX('Raw Data'!$R$4:$R$203,A156-4+1)),"") | K156: =IF(A156<>"",IF(INDEX('Raw Data'!$Q$4:$Q$203,A156-4+1)<>"",INDEX('Raw Data'!$Q$4:$Q$203,A156-4+1),""),"") | L156: =IF(NOT(A156<>""),"",IF(EXACT(TRIM(F156),"Closed"),IF(K156="",J156,MIN(J156,K156)),J156)) | M156: =IF(A156<>"",INDEX('Raw Data'!$S$4:$S$203,A156-4+1),0) -> 0 | N156: Standard | P156: 1 | Q156: =IF(O156="",0,IF(N156="Umbrella Contract",Config!$C$21,Config!$C$20)) -> 0 | R156: =IF(O156="",0,M156*Q156*P156) -> 0 | T156: 0 | U156: =IF(S156="",0,IF(N156="Umbrella Contract",Config!$C$21,Config!$C$20)) -> 0 | V156: =IF(S156="",0,M156*U156*T156) -> 0 | X156: 0 | Y156: =IF(W156="",0,IF(N156="Umbrella Contract",Config!$C$21,Config!$C$20)) -> 0 | Z156: =IF(W156="",0,M156*Y156*X156) -> 0 | AB156: =IF(OR(N156<>"Umbrella Contract",AA156=""),0,M156*Config!$C$22) -> 0 | AD156: =IF(OR(AC156="",AC156=O156,AC156=S156,AC156=W156),0,M156*Config!$C$23) -> 0 | AF156: =IF(OR(AE156="",AE156=O156,AE156=S156,AE156=W156),0,M156*Config!$C$24) -> 0 | AH156: 1 | AI156: =IF(AG156="",0,M156*Config!$C$26*AH156) -> 0 | AK156: 0 | AL156: =IF(AJ156="",0,M156*Config!$C$26*AK156) -> 0 | AN156: 0 | AO156: =IF(AM156="",0,M156*Config!$C$26*AN156) -> 0 | AP156: =IF(AND(O156="",S156="",W156=""),"",P156+T156+X156) | AQ156: =IF(R156=0,0,R156-IF((R156+V156+Z156)=0,0,(AI156+AL156+AO156)*(R156/(R156+V156+Z156)))) -> 0 | AR156: =IF(V156=0,0,V156-IF((R156+V156+Z156)=0,0,(AI156+AL156+AO156)*(V156/(R156+V156+Z156)))) -> 0 | AS156: =IF(Z156=0,0,Z156-IF((R156+V156+Z156)=0,0,(AI156+AL156+AO156)*(Z156/(R156+V156+Z156)))) -> 0
B157: =IF(A157<>"",INDEX('Raw Data'!$A$4:$A$203,A157-4+1),"") | C157: =IF(A157<>"",INDEX('Raw Data'!$B$4:$B$203,A157-4+1),"") | D157: =IF(A157<>"",INDEX('Raw Data'!$C$4:$C$203,A157-4+1),"") | E157: =IF(A157<>"",INDEX('Raw Data'!$D$4:$D$203,A157-4+1),"") | F157: =IF(A157<>"",INDEX('Raw Data'!$E$4:$E$203,A157-4+1),"") | G157: =IF(A157<>"",INDEX('Raw Data'!$H$4:$H$203,A157-4+1),"") | H157: =IF(A157<>"",INDEX('Raw Data'!$I$4:$I$203,A157-4+1),"") | I157: =IF(A157<>"",INDEX('Raw Data'!$O$4:$O$203,A157-4+1),"") | J157: =IF(A157<>"",IF(INDEX('Raw Data'!$D$4:$D$203,A157-4+1)<>"",INDEX('Raw Data'!$P$4:$P$203,A157-4+1),INDEX('Raw Data'!$R$4:$R$203,A157-4+1)),"") | K157: =IF(A157<>"",IF(INDEX('Raw Data'!$Q$4:$Q$203,A157-4+1)<>"",INDEX('Raw Data'!$Q$4:$Q$203,A157-4+1),""),"") | L157: =IF(NOT(A157<>""),"",IF(EXACT(TRIM(F157),"Closed"),IF(K157="",J157,MIN(J157,K157)),J157)) | M157: =IF(A157<>"",INDEX('Raw Data'!$S$4:$S$203,A157-4+1),0) -> 0 | N157: Standard | P157: 1 | Q157: =IF(O157="",0,IF(N157="Umbrella Contract",Config!$C$21,Config!$C$20)) -> 0 | R157: =IF(O157="",0,M157*Q157*P157) -> 0 | T157: 0 | U157: =IF(S157="",0,IF(N157="Umbrella Contract",Config!$C$21,Config!$C$20)) -> 0 | V157: =IF(S157="",0,M157*U157*T157) -> 0 | X157: 0 | Y157: =IF(W157="",0,IF(N157="Umbrella Contract",Config!$C$21,Config!$C$20)) -> 0 | Z157: =IF(W157="",0,M157*Y157*X157) -> 0 | AB157: =IF(OR(N157<>"Umbrella Contract",AA157=""),0,M157*Config!$C$22) -> 0 | AD157: =IF(OR(AC157="",AC157=O157,AC157=S157,AC157=W157),0,M157*Config!$C$23) -> 0 | AF157: =IF(OR(AE157="",AE157=O157,AE157=S157,AE157=W157),0,M157*Config!$C$24) -> 0 | AH157: 1 | AI157: =IF(AG157="",0,M157*Config!$C$26*AH157) -> 0 | AK157: 0 | AL157: =IF(AJ157="",0,M157*Config!$C$26*AK157) -> 0 | AN157: 0 | AO157: =IF(AM157="",0,M157*Config!$C$26*AN157) -> 0 | AP157: =IF(AND(O157="",S157="",W157=""),"",P157+T157+X157) | AQ157: =IF(R157=0,0,R157-IF((R157+V157+Z157)=0,0,(AI157+AL157+AO157)*(R157/(R157+V157+Z157)))) -> 0 | AR157: =IF(V157=0,0,V157-IF((R157+V157+Z157)=0,0,(AI157+AL157+AO157)*(V157/(R157+V157+Z157)))) -> 0 | AS157: =IF(Z157=0,0,Z157-IF((R157+V157+Z157)=0,0,(AI157+AL157+AO157)*(Z157/(R157+V157+Z157)))) -> 0
B158: =IF(A158<>"",INDEX('Raw Data'!$A$4:$A$203,A158-4+1),"") | C158: =IF(A158<>"",INDEX('Raw Data'!$B$4:$B$203,A158-4+1),"") | D158: =IF(A158<>"",INDEX('Raw Data'!$C$4:$C$203,A158-4+1),"") | E158: =IF(A158<>"",INDEX('Raw Data'!$D$4:$D$203,A158-4+1),"") | F158: =IF(A158<>"",INDEX('Raw Data'!$E$4:$E$203,A158-4+1),"") | G158: =IF(A158<>"",INDEX('Raw Data'!$H$4:$H$203,A158-4+1),"") | H158: =IF(A158<>"",INDEX('Raw Data'!$I$4:$I$203,A158-4+1),"") | I158: =IF(A158<>"",INDEX('Raw Data'!$O$4:$O$203,A158-4+1),"") | J158: =IF(A158<>"",IF(INDEX('Raw Data'!$D$4:$D$203,A158-4+1)<>"",INDEX('Raw Data'!$P$4:$P$203,A158-4+1),INDEX('Raw Data'!$R$4:$R$203,A158-4+1)),"") | K158: =IF(A158<>"",IF(INDEX('Raw Data'!$Q$4:$Q$203,A158-4+1)<>"",INDEX('Raw Data'!$Q$4:$Q$203,A158-4+1),""),"") | L158: =IF(NOT(A158<>""),"",IF(EXACT(TRIM(F158),"Closed"),IF(K158="",J158,MIN(J158,K158)),J158)) | M158: =IF(A158<>"",INDEX('Raw Data'!$S$4:$S$203,A158-4+1),0) -> 0 | N158: Standard | P158: 1 | Q158: =IF(O158="",0,IF(N158="Umbrella Contract",Config!$C$21,Config!$C$20)) -> 0 | R158: =IF(O158="",0,M158*Q158*P158) -> 0 | T158: 0 | U158: =IF(S158="",0,IF(N158="Umbrella Contract",Config!$C$21,Config!$C$20)) -> 0 | V158: =IF(S158="",0,M158*U158*T158) -> 0 | X158: 0 | Y158: =IF(W158="",0,IF(N158="Umbrella Contract",Config!$C$21,Config!$C$20)) -> 0 | Z158: =IF(W158="",0,M158*Y158*X158) -> 0 | AB158: =IF(OR(N158<>"Umbrella Contract",AA158=""),0,M158*Config!$C$22) -> 0 | AD158: =IF(OR(AC158="",AC158=O158,AC158=S158,AC158=W158),0,M158*Config!$C$23) -> 0 | AF158: =IF(OR(AE158="",AE158=O158,AE158=S158,AE158=W158),0,M158*Config!$C$24) -> 0 | AH158: 1 | AI158: =IF(AG158="",0,M158*Config!$C$26*AH158) -> 0 | AK158: 0 | AL158: =IF(AJ158="",0,M158*Config!$C$26*AK158) -> 0 | AN158: 0 | AO158: =IF(AM158="",0,M158*Config!$C$26*AN158) -> 0 | AP158: =IF(AND(O158="",S158="",W158=""),"",P158+T158+X158) | AQ158: =IF(R158=0,0,R158-IF((R158+V158+Z158)=0,0,(AI158+AL158+AO158)*(R158/(R158+V158+Z158)))) -> 0 | AR158: =IF(V158=0,0,V158-IF((R158+V158+Z158)=0,0,(AI158+AL158+AO158)*(V158/(R158+V158+Z158)))) -> 0 | AS158: =IF(Z158=0,0,Z158-IF((R158+V158+Z158)=0,0,(AI158+AL158+AO158)*(Z158/(R158+V158+Z158)))) -> 0
B159: =IF(A159<>"",INDEX('Raw Data'!$A$4:$A$203,A159-4+1),"") | C159: =IF(A159<>"",INDEX('Raw Data'!$B$4:$B$203,A159-4+1),"") | D159: =IF(A159<>"",INDEX('Raw Data'!$C$4:$C$203,A159-4+1),"") | E159: =IF(A159<>"",INDEX('Raw Data'!$D$4:$D$203,A159-4+1),"") | F159: =IF(A159<>"",INDEX('Raw Data'!$E$4:$E$203,A159-4+1),"") | G159: =IF(A159<>"",INDEX('Raw Data'!$H$4:$H$203,A159-4+1),"") | H159: =IF(A159<>"",INDEX('Raw Data'!$I$4:$I$203,A159-4+1),"") | I159: =IF(A159<>"",INDEX('Raw Data'!$O$4:$O$203,A159-4+1),"") | J159: =IF(A159<>"",IF(INDEX('Raw Data'!$D$4:$D$203,A159-4+1)<>"",INDEX('Raw Data'!$P$4:$P$203,A159-4+1),INDEX('Raw Data'!$R$4:$R$203,A159-4+1)),"") | K159: =IF(A159<>"",IF(INDEX('Raw Data'!$Q$4:$Q$203,A159-4+1)<>"",INDEX('Raw Data'!$Q$4:$Q$203,A159-4+1),""),"") | L159: =IF(NOT(A159<>""),"",IF(EXACT(TRIM(F159),"Closed"),IF(K159="",J159,MIN(J159,K159)),J159)) | M159: =IF(A159<>"",INDEX('Raw Data'!$S$4:$S$203,A159-4+1),0) -> 0 | N159: Standard | P159: 1 | Q159: =IF(O159="",0,IF(N159="Umbrella Contract",Config!$C$21,Config!$C$20)) -> 0 | R159: =IF(O159="",0,M159*Q159*P159) -> 0 | T159: 0 | U159: =IF(S159="",0,IF(N159="Umbrella Contract",Config!$C$21,Config!$C$20)) -> 0 | V159: =IF(S159="",0,M159*U159*T159) -> 0 | X159: 0 | Y159: =IF(W159="",0,IF(N159="Umbrella Contract",Config!$C$21,Config!$C$20)) -> 0 | Z159: =IF(W159="",0,M159*Y159*X159) -> 0 | AB159: =IF(OR(N159<>"Umbrella Contract",AA159=""),0,M159*Config!$C$22) -> 0 | AD159: =IF(OR(AC159="",AC159=O159,AC159=S159,AC159=W159),0,M159*Config!$C$23) -> 0 | AF159: =IF(OR(AE159="",AE159=O159,AE159=S159,AE159=W159),0,M159*Config!$C$24) -> 0 | AH159: 1 | AI159: =IF(AG159="",0,M159*Config!$C$26*AH159) -> 0 | AK159: 0 | AL159: =IF(AJ159="",0,M159*Config!$C$26*AK159) -> 0 | AN159: 0 | AO159: =IF(AM159="",0,M159*Config!$C$26*AN159) -> 0 | AP159: =IF(AND(O159="",S159="",W159=""),"",P159+T159+X159) | AQ159: =IF(R159=0,0,R159-IF((R159+V159+Z159)=0,0,(AI159+AL159+AO159)*(R159/(R159+V159+Z159)))) -> 0 | AR159: =IF(V159=0,0,V159-IF((R159+V159+Z159)=0,0,(AI159+AL159+AO159)*(V159/(R159+V159+Z159)))) -> 0 | AS159: =IF(Z159=0,0,Z159-IF((R159+V159+Z159)=0,0,(AI159+AL159+AO159)*(Z159/(R159+V159+Z159)))) -> 0
B160: =IF(A160<>"",INDEX('Raw Data'!$A$4:$A$203,A160-4+1),"") | C160: =IF(A160<>"",INDEX('Raw Data'!$B$4:$B$203,A160-4+1),"") | D160: =IF(A160<>"",INDEX('Raw Data'!$C$4:$C$203,A160-4+1),"") | E160: =IF(A160<>"",INDEX('Raw Data'!$D$4:$D$203,A160-4+1),"") | F160: =IF(A160<>"",INDEX('Raw Data'!$E$4:$E$203,A160-4+1),"") | G160: =IF(A160<>"",INDEX('Raw Data'!$H$4:$H$203,A160-4+1),"") | H160: =IF(A160<>"",INDEX('Raw Data'!$I$4:$I$203,A160-4+1),"") | I160: =IF(A160<>"",INDEX('Raw Data'!$O$4:$O$203,A160-4+1),"") | J160: =IF(A160<>"",IF(INDEX('Raw Data'!$D$4:$D$203,A160-4+1)<>"",INDEX('Raw Data'!$P$4:$P$203,A160-4+1),INDEX('Raw Data'!$R$4:$R$203,A160-4+1)),"") | K160: =IF(A160<>"",IF(INDEX('Raw Data'!$Q$4:$Q$203,A160-4+1)<>"",INDEX('Raw Data'!$Q$4:$Q$203,A160-4+1),""),"") | L160: =IF(NOT(A160<>""),"",IF(EXACT(TRIM(F160),"Closed"),IF(K160="",J160,MIN(J160,K160)),J160)) | M160: =IF(A160<>"",INDEX('Raw Data'!$S$4:$S$203,A160-4+1),0) -> 0 | N160: Standard | P160: 1 | Q160: =IF(O160="",0,IF(N160="Umbrella Contract",Config!$C$21,Config!$C$20)) -> 0 | R160: =IF(O160="",0,M160*Q160*P160) -> 0 | T160: 0 | U160: =IF(S160="",0,IF(N160="Umbrella Contract",Config!$C$21,Config!$C$20)) -> 0 | V160: =IF(S160="",0,M160*U160*T160) -> 0 | X160: 0 | Y160: =IF(W160="",0,IF(N160="Umbrella Contract",Config!$C$21,Config!$C$20)) -> 0 | Z160: =IF(W160="",0,M160*Y160*X160) -> 0 | AB160: =IF(OR(N160<>"Umbrella Contract",AA160=""),0,M160*Config!$C$22) -> 0 | AD160: =IF(OR(AC160="",AC160=O160,AC160=S160,AC160=W160),0,M160*Config!$C$23) -> 0 | AF160: =IF(OR(AE160="",AE160=O160,AE160=S160,AE160=W160),0,M160*Config!$C$24) -> 0 | AH160: 1 | AI160: =IF(AG160="",0,M160*Config!$C$26*AH160) -> 0 | AK160: 0 | AL160: =IF(AJ160="",0,M160*Config!$C$26*AK160) -> 0 | AN160: 0 | AO160: =IF(AM160="",0,M160*Config!$C$26*AN160) -> 0 | AP160: =IF(AND(O160="",S160="",W160=""),"",P160+T160+X160) | AQ160: =IF(R160=0,0,R160-IF((R160+V160+Z160)=0,0,(AI160+AL160+AO160)*(R160/(R160+V160+Z160)))) -> 0 | AR160: =IF(V160=0,0,V160-IF((R160+V160+Z160)=0,0,(AI160+AL160+AO160)*(V160/(R160+V160+Z160)))) -> 0 | AS160: =IF(Z160=0,0,Z160-IF((R160+V160+Z160)=0,0,(AI160+AL160+AO160)*(Z160/(R160+V160+Z160)))) -> 0
B161: =IF(A161<>"",INDEX('Raw Data'!$A$4:$A$203,A161-4+1),"") | C161: =IF(A161<>"",INDEX('Raw Data'!$B$4:$B$203,A161-4+1),"") | D161: =IF(A161<>"",INDEX('Raw Data'!$C$4:$C$203,A161-4+1),"") | E161: =IF(A161<>"",INDEX('Raw Data'!$D$4:$D$203,A161-4+1),"") | F161: =IF(A161<>"",INDEX('Raw Data'!$E$4:$E$203,A161-4+1),"") | G161: =IF(A161<>"",INDEX('Raw Data'!$H$4:$H$203,A161-4+1),"") | H161: =IF(A161<>"",INDEX('Raw Data'!$I$4:$I$203,A161-4+1),"") | I161: =IF(A161<>"",INDEX('Raw Data'!$O$4:$O$203,A161-4+1),"") | J161: =IF(A161<>"",IF(INDEX('Raw Data'!$D$4:$D$203,A161-4+1)<>"",INDEX('Raw Data'!$P$4:$P$203,A161-4+1),INDEX('Raw Data'!$R$4:$R$203,A161-4+1)),"") | K161: =IF(A161<>"",IF(INDEX('Raw Data'!$Q$4:$Q$203,A161-4+1)<>"",INDEX('Raw Data'!$Q$4:$Q$203,A161-4+1),""),"") | L161: =IF(NOT(A161<>""),"",IF(EXACT(TRIM(F161),"Closed"),IF(K161="",J161,MIN(J161,K161)),J161)) | M161: =IF(A161<>"",INDEX('Raw Data'!$S$4:$S$203,A161-4+1),0) -> 0 | N161: Standard | P161: 1 | Q161: =IF(O161="",0,IF(N161="Umbrella Contract",Config!$C$21,Config!$C$20)) -> 0 | R161: =IF(O161="",0,M161*Q161*P161) -> 0 | T161: 0 | U161: =IF(S161="",0,IF(N161="Umbrella Contract",Config!$C$21,Config!$C$20)) -> 0 | V161: =IF(S161="",0,M161*U161*T161) -> 0 | X161: 0 | Y161: =IF(W161="",0,IF(N161="Umbrella Contract",Config!$C$21,Config!$C$20)) -> 0 | Z161: =IF(W161="",0,M161*Y161*X161) -> 0 | AB161: =IF(OR(N161<>"Umbrella Contract",AA161=""),0,M161*Config!$C$22) -> 0 | AD161: =IF(OR(AC161="",AC161=O161,AC161=S161,AC161=W161),0,M161*Config!$C$23) -> 0 | AF161: =IF(OR(AE161="",AE161=O161,AE161=S161,AE161=W161),0,M161*Config!$C$24) -> 0 | AH161: 1 | AI161: =IF(AG161="",0,M161*Config!$C$26*AH161) -> 0 | AK161: 0 | AL161: =IF(AJ161="",0,M161*Config!$C$26*AK161) -> 0 | AN161: 0 | AO161: =IF(AM161="",0,M161*Config!$C$26*AN161) -> 0 | AP161: =IF(AND(O161="",S161="",W161=""),"",P161+T161+X161) | AQ161: =IF(R161=0,0,R161-IF((R161+V161+Z161)=0,0,(AI161+AL161+AO161)*(R161/(R161+V161+Z161)))) -> 0 | AR161: =IF(V161=0,0,V161-IF((R161+V161+Z161)=0,0,(AI161+AL161+AO161)*(V161/(R161+V161+Z161)))) -> 0 | AS161: =IF(Z161=0,0,Z161-IF((R161+V161+Z161)=0,0,(AI161+AL161+AO161)*(Z161/(R161+V161+Z161)))) -> 0
B162: =IF(A162<>"",INDEX('Raw Data'!$A$4:$A$203,A162-4+1),"") | C162: =IF(A162<>"",INDEX('Raw Data'!$B$4:$B$203,A162-4+1),"") | D162: =IF(A162<>"",INDEX('Raw Data'!$C$4:$C$203,A162-4+1),"") | E162: =IF(A162<>"",INDEX('Raw Data'!$D$4:$D$203,A162-4+1),"") | F162: =IF(A162<>"",INDEX('Raw Data'!$E$4:$E$203,A162-4+1),"") | G162: =IF(A162<>"",INDEX('Raw Data'!$H$4:$H$203,A162-4+1),"") | H162: =IF(A162<>"",INDEX('Raw Data'!$I$4:$I$203,A162-4+1),"") | I162: =IF(A162<>"",INDEX('Raw Data'!$O$4:$O$203,A162-4+1),"") | J162: =IF(A162<>"",IF(INDEX('Raw Data'!$D$4:$D$203,A162-4+1)<>"",INDEX('Raw Data'!$P$4:$P$203,A162-4+1),INDEX('Raw Data'!$R$4:$R$203,A162-4+1)),"") | K162: =IF(A162<>"",IF(INDEX('Raw Data'!$Q$4:$Q$203,A162-4+1)<>"",INDEX('Raw Data'!$Q$4:$Q$203,A162-4+1),""),"") | L162: =IF(NOT(A162<>""),"",IF(EXACT(TRIM(F162),"Closed"),IF(K162="",J162,MIN(J162,K162)),J162)) | M162: =IF(A162<>"",INDEX('Raw Data'!$S$4:$S$203,A162-4+1),0) -> 0 | N162: Standard | P162: 1 | Q162: =IF(O162="",0,IF(N162="Umbrella Contract",Config!$C$21,Config!$C$20)) -> 0 | R162: =IF(O162="",0,M162*Q162*P162) -> 0 | T162: 0 | U162: =IF(S162="",0,IF(N162="Umbrella Contract",Config!$C$21,Config!$C$20)) -> 0 | V162: =IF(S162="",0,M162*U162*T162) -> 0 | X162: 0 | Y162: =IF(W162="",0,IF(N162="Umbrella Contract",Config!$C$21,Config!$C$20)) -> 0 | Z162: =IF(W162="",0,M162*Y162*X162) -> 0 | AB162: =IF(OR(N162<>"Umbrella Contract",AA162=""),0,M162*Config!$C$22) -> 0 | AD162: =IF(OR(AC162="",AC162=O162,AC162=S162,AC162=W162),0,M162*Config!$C$23) -> 0 | AF162: =IF(OR(AE162="",AE162=O162,AE162=S162,AE162=W162),0,M162*Config!$C$24) -> 0 | AH162: 1 | AI162: =IF(AG162="",0,M162*Config!$C$26*AH162) -> 0 | AK162: 0 | AL162: =IF(AJ162="",0,M162*Config!$C$26*AK162) -> 0 | AN162: 0 | AO162: =IF(AM162="",0,M162*Config!$C$26*AN162) -> 0 | AP162: =IF(AND(O162="",S162="",W162=""),"",P162+T162+X162) | AQ162: =IF(R162=0,0,R162-IF((R162+V162+Z162)=0,0,(AI162+AL162+AO162)*(R162/(R162+V162+Z162)))) -> 0 | AR162: =IF(V162=0,0,V162-IF((R162+V162+Z162)=0,0,(AI162+AL162+AO162)*(V162/(R162+V162+Z162)))) -> 0 | AS162: =IF(Z162=0,0,Z162-IF((R162+V162+Z162)=0,0,(AI162+AL162+AO162)*(Z162/(R162+V162+Z162)))) -> 0
B163: =IF(A163<>"",INDEX('Raw Data'!$A$4:$A$203,A163-4+1),"") | C163: =IF(A163<>"",INDEX('Raw Data'!$B$4:$B$203,A163-4+1),"") | D163: =IF(A163<>"",INDEX('Raw Data'!$C$4:$C$203,A163-4+1),"") | E163: =IF(A163<>"",INDEX('Raw Data'!$D$4:$D$203,A163-4+1),"") | F163: =IF(A163<>"",INDEX('Raw Data'!$E$4:$E$203,A163-4+1),"") | G163: =IF(A163<>"",INDEX('Raw Data'!$H$4:$H$203,A163-4+1),"") | H163: =IF(A163<>"",INDEX('Raw Data'!$I$4:$I$203,A163-4+1),"") | I163: =IF(A163<>"",INDEX('Raw Data'!$O$4:$O$203,A163-4+1),"") | J163: =IF(A163<>"",IF(INDEX('Raw Data'!$D$4:$D$203,A163-4+1)<>"",INDEX('Raw Data'!$P$4:$P$203,A163-4+1),INDEX('Raw Data'!$R$4:$R$203,A163-4+1)),"") | K163: =IF(A163<>"",IF(INDEX('Raw Data'!$Q$4:$Q$203,A163-4+1)<>"",INDEX('Raw Data'!$Q$4:$Q$203,A163-4+1),""),"") | L163: =IF(NOT(A163<>""),"",IF(EXACT(TRIM(F163),"Closed"),IF(K163="",J163,MIN(J163,K163)),J163)) | M163: =IF(A163<>"",INDEX('Raw Data'!$S$4:$S$203,A163-4+1),0) -> 0 | N163: Standard | P163: 1 | Q163: =IF(O163="",0,IF(N163="Umbrella Contract",Config!$C$21,Config!$C$20)) -> 0 | R163: =IF(O163="",0,M163*Q163*P163) -> 0 | T163: 0 | U163: =IF(S163="",0,IF(N163="Umbrella Contract",Config!$C$21,Config!$C$20)) -> 0 | V163: =IF(S163="",0,M163*U163*T163) -> 0 | X163: 0 | Y163: =IF(W163="",0,IF(N163="Umbrella Contract",Config!$C$21,Config!$C$20)) -> 0 | Z163: =IF(W163="",0,M163*Y163*X163) -> 0 | AB163: =IF(OR(N163<>"Umbrella Contract",AA163=""),0,M163*Config!$C$22) -> 0 | AD163: =IF(OR(AC163="",AC163=O163,AC163=S163,AC163=W163),0,M163*Config!$C$23) -> 0 | AF163: =IF(OR(AE163="",AE163=O163,AE163=S163,AE163=W163),0,M163*Config!$C$24) -> 0 | AH163: 1 | AI163: =IF(AG163="",0,M163*Config!$C$26*AH163) -> 0 | AK163: 0 | AL163: =IF(AJ163="",0,M163*Config!$C$26*AK163) -> 0 | AN163: 0 | AO163: =IF(AM163="",0,M163*Config!$C$26*AN163) -> 0 | AP163: =IF(AND(O163="",S163="",W163=""),"",P163+T163+X163) | AQ163: =IF(R163=0,0,R163-IF((R163+V163+Z163)=0,0,(AI163+AL163+AO163)*(R163/(R163+V163+Z163)))) -> 0 | AR163: =IF(V163=0,0,V163-IF((R163+V163+Z163)=0,0,(AI163+AL163+AO163)*(V163/(R163+V163+Z163)))) -> 0 | AS163: =IF(Z163=0,0,Z163-IF((R163+V163+Z163)=0,0,(AI163+AL163+AO163)*(Z163/(R163+V163+Z163)))) -> 0
B164: =IF(A164<>"",INDEX('Raw Data'!$A$4:$A$203,A164-4+1),"") | C164: =IF(A164<>"",INDEX('Raw Data'!$B$4:$B$203,A164-4+1),"") | D164: =IF(A164<>"",INDEX('Raw Data'!$C$4:$C$203,A164-4+1),"") | E164: =IF(A164<>"",INDEX('Raw Data'!$D$4:$D$203,A164-4+1),"") | F164: =IF(A164<>"",INDEX('Raw Data'!$E$4:$E$203,A164-4+1),"") | G164: =IF(A164<>"",INDEX('Raw Data'!$H$4:$H$203,A164-4+1),"") | H164: =IF(A164<>"",INDEX('Raw Data'!$I$4:$I$203,A164-4+1),"") | I164: =IF(A164<>"",INDEX('Raw Data'!$O$4:$O$203,A164-4+1),"") | J164: =IF(A164<>"",IF(INDEX('Raw Data'!$D$4:$D$203,A164-4+1)<>"",INDEX('Raw Data'!$P$4:$P$203,A164-4+1),INDEX('Raw Data'!$R$4:$R$203,A164-4+1)),"") | K164: =IF(A164<>"",IF(INDEX('Raw Data'!$Q$4:$Q$203,A164-4+1)<>"",INDEX('Raw Data'!$Q$4:$Q$203,A164-4+1),""),"") | L164: =IF(NOT(A164<>""),"",IF(EXACT(TRIM(F164),"Closed"),IF(K164="",J164,MIN(J164,K164)),J164)) | M164: =IF(A164<>"",INDEX('Raw Data'!$S$4:$S$203,A164-4+1),0) -> 0 | N164: Standard | P164: 1 | Q164: =IF(O164="",0,IF(N164="Umbrella Contract",Config!$C$21,Config!$C$20)) -> 0 | R164: =IF(O164="",0,M164*Q164*P164) -> 0 | T164: 0 | U164: =IF(S164="",0,IF(N164="Umbrella Contract",Config!$C$21,Config!$C$20)) -> 0 | V164: =IF(S164="",0,M164*U164*T164) -> 0 | X164: 0 | Y164: =IF(W164="",0,IF(N164="Umbrella Contract",Config!$C$21,Config!$C$20)) -> 0 | Z164: =IF(W164="",0,M164*Y164*X164) -> 0 | AB164: =IF(OR(N164<>"Umbrella Contract",AA164=""),0,M164*Config!$C$22) -> 0 | AD164: =IF(OR(AC164="",AC164=O164,AC164=S164,AC164=W164),0,M164*Config!$C$23) -> 0 | AF164: =IF(OR(AE164="",AE164=O164,AE164=S164,AE164=W164),0,M164*Config!$C$24) -> 0 | AH164: 1 | AI164: =IF(AG164="",0,M164*Config!$C$26*AH164) -> 0 | AK164: 0 | AL164: =IF(AJ164="",0,M164*Config!$C$26*AK164) -> 0 | AN164: 0 | AO164: =IF(AM164="",0,M164*Config!$C$26*AN164) -> 0 | AP164: =IF(AND(O164="",S164="",W164=""),"",P164+T164+X164) | AQ164: =IF(R164=0,0,R164-IF((R164+V164+Z164)=0,0,(AI164+AL164+AO164)*(R164/(R164+V164+Z164)))) -> 0 | AR164: =IF(V164=0,0,V164-IF((R164+V164+Z164)=0,0,(AI164+AL164+AO164)*(V164/(R164+V164+Z164)))) -> 0 | AS164: =IF(Z164=0,0,Z164-IF((R164+V164+Z164)=0,0,(AI164+AL164+AO164)*(Z164/(R164+V164+Z164)))) -> 0
B165: =IF(A165<>"",INDEX('Raw Data'!$A$4:$A$203,A165-4+1),"") | C165: =IF(A165<>"",INDEX('Raw Data'!$B$4:$B$203,A165-4+1),"") | D165: =IF(A165<>"",INDEX('Raw Data'!$C$4:$C$203,A165-4+1),"") | E165: =IF(A165<>"",INDEX('Raw Data'!$D$4:$D$203,A165-4+1),"") | F165: =IF(A165<>"",INDEX('Raw Data'!$E$4:$E$203,A165-4+1),"") | G165: =IF(A165<>"",INDEX('Raw Data'!$H$4:$H$203,A165-4+1),"") | H165: =IF(A165<>"",INDEX('Raw Data'!$I$4:$I$203,A165-4+1),"") | I165: =IF(A165<>"",INDEX('Raw Data'!$O$4:$O$203,A165-4+1),"") | J165: =IF(A165<>"",IF(INDEX('Raw Data'!$D$4:$D$203,A165-4+1)<>"",INDEX('Raw Data'!$P$4:$P$203,A165-4+1),INDEX('Raw Data'!$R$4:$R$203,A165-4+1)),"") | K165: =IF(A165<>"",IF(INDEX('Raw Data'!$Q$4:$Q$203,A165-4+1)<>"",INDEX('Raw Data'!$Q$4:$Q$203,A165-4+1),""),"") | L165: =IF(NOT(A165<>""),"",IF(EXACT(TRIM(F165),"Closed"),IF(K165="",J165,MIN(J165,K165)),J165)) | M165: =IF(A165<>"",INDEX('Raw Data'!$S$4:$S$203,A165-4+1),0) -> 0 | N165: Standard | P165: 1 | Q165: =IF(O165="",0,IF(N165="Umbrella Contract",Config!$C$21,Config!$C$20)) -> 0 | R165: =IF(O165="",0,M165*Q165*P165) -> 0 | T165: 0 | U165: =IF(S165="",0,IF(N165="Umbrella Contract",Config!$C$21,Config!$C$20)) -> 0 | V165: =IF(S165="",0,M165*U165*T165) -> 0 | X165: 0 | Y165: =IF(W165="",0,IF(N165="Umbrella Contract",Config!$C$21,Config!$C$20)) -> 0 | Z165: =IF(W165="",0,M165*Y165*X165) -> 0 | AB165: =IF(OR(N165<>"Umbrella Contract",AA165=""),0,M165*Config!$C$22) -> 0 | AD165: =IF(OR(AC165="",AC165=O165,AC165=S165,AC165=W165),0,M165*Config!$C$23) -> 0 | AF165: =IF(OR(AE165="",AE165=O165,AE165=S165,AE165=W165),0,M165*Config!$C$24) -> 0 | AH165: 1 | AI165: =IF(AG165="",0,M165*Config!$C$26*AH165) -> 0 | AK165: 0 | AL165: =IF(AJ165="",0,M165*Config!$C$26*AK165) -> 0 | AN165: 0 | AO165: =IF(AM165="",0,M165*Config!$C$26*AN165) -> 0 | AP165: =IF(AND(O165="",S165="",W165=""),"",P165+T165+X165) | AQ165: =IF(R165=0,0,R165-IF((R165+V165+Z165)=0,0,(AI165+AL165+AO165)*(R165/(R165+V165+Z165)))) -> 0 | AR165: =IF(V165=0,0,V165-IF((R165+V165+Z165)=0,0,(AI165+AL165+AO165)*(V165/(R165+V165+Z165)))) -> 0 | AS165: =IF(Z165=0,0,Z165-IF((R165+V165+Z165)=0,0,(AI165+AL165+AO165)*(Z165/(R165+V165+Z165)))) -> 0
... B205: =IF(A205<>"",INDEX('Raw Data'!$A$4:$A$203,A205-4+1),"") | C205: =IF(A205<>"",INDEX('Raw Data'!$B$4:$B$203,A205-4+1),"") | D205: =IF(A205<>"",INDEX('Raw Data'!$C$4:$C$203,A205-4+1),"") | E205: =IF(A205<>"",INDEX('Raw Data'!$D$4:$D$203,A205-4+1),"") | F205: =IF(A205<>"",INDEX('Raw Data'!$E$4:$E$203,A205-4+1),"") | G205: =IF(A205<>"",INDEX('Raw Data'!$H$4:$H$203,A205-4+1),"") | H205: =IF(A205<>"",INDEX('Raw Data'!$I$4:$I$203,A205-4+1),"") | I205: =IF(A205<>"",INDEX('Raw Data'!$O$4:$O$203,A205-4+1),"") | J205: =IF(A205<>"",IF(INDEX('Raw Data'!$D$4:$D$203,A205-4+1)<>"",INDEX('Raw Data'!$P$4:$P$203,A205-4+1),INDEX('Raw Data'!$R$4:$R$203,A205-4+1)),"") | K205: =IF(A205<>"",IF(INDEX('Raw Data'!$Q$4:$Q$203,A205-4+1)<>"",INDEX('Raw Data'!$Q$4:$Q$203,A205-4+1),""),"") | L205: =IF(NOT(A205<>""),"",IF(EXACT(TRIM(F205),"Closed"),IF(K205="",J205,MIN(J205,K205)),J205)) | M205: =IF(A205<>"",INDEX('Raw Data'!$S$4:$S$203,A205-4+1),0) -> 0 | N205: Standard | P205: 1 | Q205: =IF(O205="",0,IF(N205="Umbrella Contract",Config!$C$21,Config!$C$20)) -> 0 | R205: =IF(O205="",0,M205*Q205*P205) -> 0 | T205: 0 | U205: =IF(S205="",0,IF(N205="Umbrella Contract",Config!$C$21,Config!$C$20)) -> 0 | V205: =IF(S205="",0,M205*U205*T205) -> 0 | X205: 0 | Y205: =IF(W205="",0,IF(N205="Umbrella Contract",Config!$C$21,Config!$C$20)) -> 0 | Z205: =IF(W205="",0,M205*Y205*X205) -> 0 | AB205: =IF(OR(N205<>"Umbrella Contract",AA205=""),0,M205*Config!$C$22) -> 0 | AD205: =IF(OR(AC205="",AC205=O205,AC205=S205,AC205=W205),0,M205*Config!$C$23) -> 0 | AF205: =IF(OR(AE205="",AE205=O205,AE205=S205,AE205=W205),0,M205*Config!$C$24) -> 0 | AH205: 1 | AI205: =IF(AG205="",0,M205*Config!$C$26*AH205) -> 0 | AK205: 0 | AL205: =IF(AJ205="",0,M205*Config!$C$26*AK205) -> 0 | AN205: 0 | AO205: =IF(AM205="",0,M205*Config!$C$26*AN205) -> 0 | AP205: =IF(AND(O205="",S205="",W205=""),"",P205+T205+X205) | AQ205: =IF(R205=0,0,R205-IF((R205+V205+Z205)=0,0,(AI205+AL205+AO205)*(R205/(R205+V205+Z205)))) -> 0 | AR205: =IF(V205=0,0,V205-IF((R205+V205+Z205)=0,0,(AI205+AL205+AO205)*(V205/(R205+V205+Z205)))) -> 0 | AS205: =IF(Z205=0,0,Z205-IF((R205+V205+Z205)=0,0,(AI205+AL205+AO205)*(Z205/(R205+V205+Z205)))) -> 0
B207: GRAND TOTAL | I207: =SUM(I7:I205) -> 1352400000 | M207: =SUM(M7:M205) -> 435610000 | R207: =SUM(R7:R205) -> 16758000 | V207: =SUM(V7:V205) -> 2450000 | Z207: =SUM(Z7:Z205) -> 0 | AB207: =SUM(AB7:AB205) -> 2572500 | AD207: =SUM(AD7:AD205) -> 3049270 | AF207: =SUM(AF7:AF205) -> 1306830 | AI207: =SUM(AI7:AI205) -> 705600 | AL207: =SUM(AL7:AL205) -> 0 | AO207: =SUM(AO7:AO205) -> 0 | AQ207: =SUM(AQ7:AQ205) -> 16052400 | AR207: =SUM(AR7:AR205) -> 2450000 | AS207: =SUM(AS7:AS205) -> 0

Sheet Commission Data — Presales
A1: =Config!C11&" — COMMISSION DATA | PRESALES" -> PT ITSEC ASIA — SALES COMMISSION TRACKER Q1 2026 — COMMISSION DATA | PRESALES
A2: =Config!C7&" | Payout: "&TEXT(Config!C10,"DD-MMM-YYYY")&" | Presales rate: 3.5%×share | Up to 3 presales persons" -> Q1 2026 | Payout: 30-Apr-2026 | Presales rate: 3.5%×share | Up to 3 presales persons
A3: ="Quarter: "&Config!C7&" | "&TEXT(Config!C8,"DD-MMM-YYYY")&" → "&TEXT(Config!C9,"DD-MMM-YYYY") -> Quarter: Q1 2026 | 01-Jan-2026 → 31-Mar-2026
A5: DEAL INFO | E5: FINANCIALS & MARGIN | N5: PRESALES (up to 3) | W5: PS Share ⚠
A6: # | B6: Service Type | C6: Client | D6: Invoice | E6: PSOHUB | F6: Status | G6: Description | H6: Date | I6: Rev Net | J6: Est. Margin | K6: Final Margin | L6: APPLIED MARGIN | M6: Comm Base | N6: PS 1 Name | O6: PS 1 Share% | P6: PS 1 Comm | Q6: PS 2 Name | R6: PS 2 Share% | S6: PS 2 Comm | T6: PS 3 Name | U6: PS 3 Share% | V6: PS 3 Comm | W6: PS Share ⚠
A7: 4 | B7: =IF(A7<>"",INDEX('Raw Data'!$A$4:$A$203,A7-4+1),"") -> Pentest | C7: =IF(A7<>"",INDEX('Raw Data'!$B$4:$B$203,A7-4+1),"") -> PT Dummy Bank Tbk | D7: =IF(A7<>"",INDEX('Raw Data'!$C$4:$C$203,A7-4+1),"") -> INV-990001 | E7: =IF(A7<>"",INDEX('Raw Data'!$D$4:$D$203,A7-4+1),"") -> PRO-2026-901 | F7: =IF(A7<>"",INDEX('Raw Data'!$E$4:$E$203,A7-4+1),"") -> Closed | G7: =IF(A7<>"",INDEX('Raw Data'!$H$4:$H$203,A7-4+1),"") -> Web Application Penetration Test - Phase 1 | H7: =IF(A7<>"",INDEX('Raw Data'!$I$4:$I$203,A7-4+1),"") -> 46037 | I7: =IF(A7<>"",INDEX('Raw Data'!$O$4:$O$203,A7-4+1),"") -> 196000000 | J7: =IF(A7<>"",IF(INDEX('Raw Data'!$D$4:$D$203,A7-4+1)<>"",INDEX('Raw Data'!$P$4:$P$203,A7-4+1),INDEX('Raw Data'!$R$4:$R$203,A7-4+1)),"") -> 0 | K7: =IF(A7<>"",IF(INDEX('Raw Data'!$Q$4:$Q$203,A7-4+1)<>"",INDEX('Raw Data'!$Q$4:$Q$203,A7-4+1),""),"") -> 0.45 | L7: =IF(NOT(A7<>""),"",IF(EXACT(TRIM(F7),"Closed"),IF(K7="",J7,MIN(J7,K7)),J7)) -> 0 | M7: =IF(A7<>"",INDEX('Raw Data'!$S$4:$S$203,A7-4+1),0) -> 88200000 | N7: Andy Wijaya | O7: 1 | P7: =IF(N7="",0,M7*Config!$C$25*O7) -> 3087000 | R7: 0 | S7: =IF(Q7="",0,M7*Config!$C$25*R7) -> 0 | U7: 0 | V7: =IF(T7="",0,M7*Config!$C$25*U7) -> 0 | W7: =IF(AND(N7="",Q7="",T7=""),"",O7+R7+U7) -> 1
A8: 5 | B8: =IF(A8<>"",INDEX('Raw Data'!$A$4:$A$203,A8-4+1),"") -> Governance | C8: =IF(A8<>"",INDEX('Raw Data'!$B$4:$B$203,A8-4+1),"") -> PT Dummy Insurance | D8: =IF(A8<>"",INDEX('Raw Data'!$C$4:$C$203,A8-4+1),"") -> INV-990002 | E8: =IF(A8<>"",INDEX('Raw Data'!$D$4:$D$203,A8-4+1),"") -> PRO-2026-902 | F8: =IF(A8<>"",INDEX('Raw Data'!$E$4:$E$203,A8-4+1),"") -> Active | G8: =IF(A8<>"",INDEX('Raw Data'!$H$4:$H$203,A8-4+1),"") -> GRC Framework Assessment & Remediation Term 1 - 50% | H8: =IF(A8<>"",INDEX('Raw Data'!$I$4:$I$203,A8-4+1),"") -> 46063 | I8: =IF(A8<>"",INDEX('Raw Data'!$O$4:$O$203,A8-4+1),"") -> 147000000 | J8: =IF(A8<>"",IF(INDEX('Raw Data'!$D$4:$D$203,A8-4+1)<>"",INDEX('Raw Data'!$P$4:$P$203,A8-4+1),INDEX('Raw Data'!$R$4:$R$203,A8-4+1)),"") -> 0.35 | K8: =IF(A8<>"",IF(INDEX('Raw Data'!$Q$4:$Q$203,A8-4+1)<>"",INDEX('Raw Data'!$Q$4:$Q$203,A8-4+1),""),"") | L8: =IF(NOT(A8<>""),"",IF(EXACT(TRIM(F8),"Closed"),IF(K8="",J8,MIN(J8,K8)),J8)) -> 0.35 | M8: =IF(A8<>"",INDEX('Raw Data'!$S$4:$S$203,A8-4+1),0) -> 51450000 | O8: 1 | P8: =IF(N8="",0,M8*Config!$C$25*O8) -> 0 | R8: 0 | S8: =IF(Q8="",0,M8*Config!$C$25*R8) -> 0 | U8: 0 | V8: =IF(T8="",0,M8*Config!$C$25*U8) -> 0 | W8: =IF(AND(N8="",Q8="",T8=""),"",O8+R8+U8)
A9: 6 | B9: =IF(A9<>"",INDEX('Raw Data'!$A$4:$A$203,A9-4+1),"") -> Solution | C9: =IF(A9<>"",INDEX('Raw Data'!$B$4:$B$203,A9-4+1),"") -> PT Dummy Telco | D9: =IF(A9<>"",INDEX('Raw Data'!$C$4:$C$203,A9-4+1),"") -> INV-990003 | E9: =IF(A9<>"",INDEX('Raw Data'!$D$4:$D$203,A9-4+1),"") -> PRO-2026-903 | F9: =IF(A9<>"",INDEX('Raw Data'!$E$4:$E$203,A9-4+1),"") -> Closed | G9: =IF(A9<>"",INDEX('Raw Data'!$H$4:$H$203,A9-4+1),"") -> Managed SOC Services - Month 3 | H9: =IF(A9<>"",INDEX('Raw Data'!$I$4:$I$203,A9-4+1),"") -> 46082 | I9: =IF(A9<>"",INDEX('Raw Data'!$O$4:$O$203,A9-4+1),"") -> 343000000 | J9: =IF(A9<>"",IF(INDEX('Raw Data'!$D$4:$D$203,A9-4+1)<>"",INDEX('Raw Data'!$P$4:$P$203,A9-4+1),INDEX('Raw Data'!$R$4:$R$203,A9-4+1)),"") -> 0 | K9: =IF(A9<>"",IF(INDEX('Raw Data'!$Q$4:$Q$203,A9-4+1)<>"",INDEX('Raw Data'!$Q$4:$Q$203,A9-4+1),""),"") -> 0.3 | L9: =IF(NOT(A9<>""),"",IF(EXACT(TRIM(F9),"Closed"),IF(K9="",J9,MIN(J9,K9)),J9)) -> 0 | M9: =IF(A9<>"",INDEX('Raw Data'!$S$4:$S$203,A9-4+1),0) -> 102900000 | N9: Andy Wijaya | O9: 1 | P9: =IF(N9="",0,M9*Config!$C$25*O9) -> 3601500 | R9: 0 | S9: =IF(Q9="",0,M9*Config!$C$25*R9) -> 0 | U9: 0 | V9: =IF(T9="",0,M9*Config!$C$25*U9) -> 0 | W9: =IF(AND(N9="",Q9="",T9=""),"",O9+R9+U9) -> 1
A10: 7 | B10: =IF(A10<>"",INDEX('Raw Data'!$A$4:$A$203,A10-4+1),"") -> MSS | C10: =IF(A10<>"",INDEX('Raw Data'!$B$4:$B$203,A10-4+1),"") -> PT Dummy Energy | D10: =IF(A10<>"",INDEX('Raw Data'!$C$4:$C$203,A10-4+1),"") -> INV-990004 | E10: =IF(A10<>"",INDEX('Raw Data'!$D$4:$D$203,A10-4+1),"") -> PRO-2026-904 | F10: =IF(A10<>"",INDEX('Raw Data'!$E$4:$E$203,A10-4+1),"") -> Closed - Missing Orange | G10: =IF(A10<>"",INDEX('Raw Data'!$H$4:$H$203,A10-4+1),"") -> Vulnerability Assessment & License Renewal | H10: =IF(A10<>"",INDEX('Raw Data'!$I$4:$I$203,A10-4+1),"") -> 46042 | I10: =IF(A10<>"",INDEX('Raw Data'!$O$4:$O$203,A10-4+1),"") -> 490000000 | J10: =IF(A10<>"",IF(INDEX('Raw Data'!$D$4:$D$203,A10-4+1)<>"",INDEX('Raw Data'!$P$4:$P$203,A10-4+1),INDEX('Raw Data'!$R$4:$R$203,A10-4+1)),"") -> 0.25 | K10: =IF(A10<>"",IF(INDEX('Raw Data'!$Q$4:$Q$203,A10-4+1)<>"",INDEX('Raw Data'!$Q$4:$Q$203,A10-4+1),""),"") | L10: =IF(NOT(A10<>""),"",IF(EXACT(TRIM(F10),"Closed"),IF(K10="",J10,MIN(J10,K10)),J10)) -> 0.25 | M10: =IF(A10<>"",INDEX('Raw Data'!$S$4:$S$203,A10-4+1),0) -> 122500000 | N10: Vinsensius | O10: 0.5 | P10: =IF(N10="",0,M10*Config!$C$25*O10) -> 2143750 | Q10: Anton Dwi Suhartanto | R10: 0.5 | S10: =IF(Q10="",0,M10*Config!$C$25*R10) -> 2143750 | U10: 0 | V10: =IF(T10="",0,M10*Config!$C$25*U10) -> 0 | W10: =IF(AND(N10="",Q10="",T10=""),"",O10+R10+U10) -> 1
A11: 8 | B11: =IF(A11<>"",INDEX('Raw Data'!$A$4:$A$203,A11-4+1),"") -> Forensic | C11: =IF(A11<>"",INDEX('Raw Data'!$B$4:$B$203,A11-4+1),"") -> PT Dummy Retail | D11: =IF(A11<>"",INDEX('Raw Data'!$C$4:$C$203,A11-4+1),"") -> INV-990005 | E11: =IF(A11<>"",INDEX('Raw Data'!$D$4:$D$203,A11-4+1),"") -> 0 | F11: =IF(A11<>"",INDEX('Raw Data'!$E$4:$E$203,A11-4+1),"") -> Active | G11: =IF(A11<>"",INDEX('Raw Data'!$H$4:$H$203,A11-4+1),"") -> Digital Forensic Investigation - Term 1 - 40% | H11: =IF(A11<>"",INDEX('Raw Data'!$I$4:$I$203,A11-4+1),"") -> 46101 | I11: =IF(A11<>"",INDEX('Raw Data'!$O$4:$O$203,A11-4+1),"") -> 176400000 | J11: =IF(A11<>"",IF(INDEX('Raw Data'!$D$4:$D$203,A11-4+1)<>"",INDEX('Raw Data'!$P$4:$P$203,A11-4+1),INDEX('Raw Data'!$R$4:$R$203,A11-4+1)),"") -> 0 | K11: =IF(A11<>"",IF(INDEX('Raw Data'!$Q$4:$Q$203,A11-4+1)<>"",INDEX('Raw Data'!$Q$4:$Q$203,A11-4+1),""),"") | L11: =IF(NOT(A11<>""),"",IF(EXACT(TRIM(F11),"Closed"),IF(K11="",J11,MIN(J11,K11)),J11)) -> 0 | M11: =IF(A11<>"",INDEX('Raw Data'!$S$4:$S$203,A11-4+1),0) -> 70560000 | N11: Arief Muttaqien | O11: 1 | P11: =IF(N11="",0,M11*Config!$C$25*O11) -> 2469600 | R11: 0 | S11: =IF(Q11="",0,M11*Config!$C$25*R11) -> 0 | U11: 0 | V11: =IF(T11="",0,M11*Config!$C$25*U11) -> 0 | W11: =IF(AND(N11="",Q11="",T11=""),"",O11+R11+U11) -> 1
B154: =IF(A154<>"",INDEX('Raw Data'!$A$4:$A$203,A154-4+1),"") | C154: =IF(A154<>"",INDEX('Raw Data'!$B$4:$B$203,A154-4+1),"") | D154: =IF(A154<>"",INDEX('Raw Data'!$C$4:$C$203,A154-4+1),"") | E154: =IF(A154<>"",INDEX('Raw Data'!$D$4:$D$203,A154-4+1),"") | F154: =IF(A154<>"",INDEX('Raw Data'!$E$4:$E$203,A154-4+1),"") | G154: =IF(A154<>"",INDEX('Raw Data'!$H$4:$H$203,A154-4+1),"") | H154: =IF(A154<>"",INDEX('Raw Data'!$I$4:$I$203,A154-4+1),"") | I154: =IF(A154<>"",INDEX('Raw Data'!$O$4:$O$203,A154-4+1),"") | J154: =IF(A154<>"",IF(INDEX('Raw Data'!$D$4:$D$203,A154-4+1)<>"",INDEX('Raw Data'!$P$4:$P$203,A154-4+1),INDEX('Raw Data'!$R$4:$R$203,A154-4+1)),"") | K154: =IF(A154<>"",IF(INDEX('Raw Data'!$Q$4:$Q$203,A154-4+1)<>"",INDEX('Raw Data'!$Q$4:$Q$203,A154-4+1),""),"") | L154: =IF(NOT(A154<>""),"",IF(EXACT(TRIM(F154),"Closed"),IF(K154="",J154,MIN(J154,K154)),J154)) | M154: =IF(A154<>"",I154*L154,0) -> 0 | O154: 1 | P154: =IF(N154="",0,M154*Config!$C$25*O154) -> 0 | R154: 0 | S154: =IF(Q154="",0,M154*Config!$C$25*R154) -> 0 | U154: 0 | V154: =IF(T154="",0,M154*Config!$C$25*U154) -> 0 | W154: =IF(AND(N154="",Q154="",T154=""),"",O154+R154+U154)
B155: =IF(A155<>"",INDEX('Raw Data'!$A$4:$A$203,A155-4+1),"") | C155: =IF(A155<>"",INDEX('Raw Data'!$B$4:$B$203,A155-4+1),"") | D155: =IF(A155<>"",INDEX('Raw Data'!$C$4:$C$203,A155-4+1),"") | E155: =IF(A155<>"",INDEX('Raw Data'!$D$4:$D$203,A155-4+1),"") | F155: =IF(A155<>"",INDEX('Raw Data'!$E$4:$E$203,A155-4+1),"") | G155: =IF(A155<>"",INDEX('Raw Data'!$H$4:$H$203,A155-4+1),"") | H155: =IF(A155<>"",INDEX('Raw Data'!$I$4:$I$203,A155-4+1),"") | I155: =IF(A155<>"",INDEX('Raw Data'!$O$4:$O$203,A155-4+1),"") | J155: =IF(A155<>"",IF(INDEX('Raw Data'!$D$4:$D$203,A155-4+1)<>"",INDEX('Raw Data'!$P$4:$P$203,A155-4+1),INDEX('Raw Data'!$R$4:$R$203,A155-4+1)),"") | K155: =IF(A155<>"",IF(INDEX('Raw Data'!$Q$4:$Q$203,A155-4+1)<>"",INDEX('Raw Data'!$Q$4:$Q$203,A155-4+1),""),"") | L155: =IF(NOT(A155<>""),"",IF(EXACT(TRIM(F155),"Closed"),IF(K155="",J155,MIN(J155,K155)),J155)) | M155: =IF(A155<>"",I155*L155,0) -> 0 | O155: 1 | P155: =IF(N155="",0,M155*Config!$C$25*O155) -> 0 | R155: 0 | S155: =IF(Q155="",0,M155*Config!$C$25*R155) -> 0 | U155: 0 | V155: =IF(T155="",0,M155*Config!$C$25*U155) -> 0 | W155: =IF(AND(N155="",Q155="",T155=""),"",O155+R155+U155)
